[META]
version=2.0
spawnOnBlockType=12
spawnSunlight=True
spawnDarkness=False
spawnWater=False
spawnLava=False
underFill=True
randomRotation=True
dig=False
tree=False
branch=False
rarity=1
collisionPercentage=2
spawnElevationMin=0
spawnElevationMax=128
spawnInBiome=Plains
[DATA]
-3,-4,0:17.0
3,-4,0:17.0
-3,4,0:17.0
3,4,0:17.0
3,-3,0:5.0
3,-2,0:5.0
3,-1,0:5.0
3,0,0:5.0
3,1,0:5.0
3,2,0:5.0
3,3,0:5.0
-3,3,0:5.0
-3,2,0:5.0
-3,1,0:5.0
-3,0,0:5.0
-3,-1,0:5.0
-3,-2,0:5.0
-3,-3,0:5.0
-2,-4,0:5.0
-1,-4,0:5.0
0,-4,0:5.0
1,-4,0:5.0
2,-4,0:5.0
-2,4,0:5.0
-1,4,0:5.0
1,4,0:5.0
2,4,0:5.0
0,4,0:64.0
3,-4,-1:4
2,-4,-1:4
1,-4,-1:4
0,-4,-1:4
-1,-4,-1:4
-2,-4,-1:4
-3,-4,-1:4
-3,-3,-1:4
-3,-2,-1:4
-3,-1,-1:4
-3,0,-1:4
-3,1,-1:4
-3,2,-1:4
-3,3,-1:4
-3,4,-1:4
-2,4,-1:4
-1,4,-1:4
0,4,-1:4
1,4,-1:4
2,4,-1:4
3,4,-1:4
3,3,-1:4
3,2,-1:4
3,1,-1:4
3,0,-1:4
3,-1,-1:4
3,-2,-1:4
3,-3,-1:4
2,-3,-1:4
1,-3,-1:4
0,-3,-1:4
-1,-3,-1:4
-2,-3,-1:4
-2,-2,-1:4
-1,-2,-1:4
0,-2,-1:4
1,-2,-1:4
2,-2,-1:4
2,-1,-1:4
1,-1,-1:4
0,-1,-1:4
-1,-1,-1:4
-2,-1,-1:4
-2,0,-1:4
-1,0,-1:4
0,0,-1:4
1,0,-1:4
2,0,-1:4
2,1,-1:4
1,1,-1:4
0,1,-1:4
-1,1,-1:4
-2,1,-1:4
-2,2,-1:4
-1,2,-1:4
0,2,-1:4
1,2,-1:4
2,2,-1:4
2,3,-1:4
1,3,-1:4
0,3,-1:4
-1,3,-1:4
-2,3,-1:4
3,-4,1:17.0
-3,-4,1:17.0
-3,4,1:17.0
3,4,1:17.0
-2,-4,1:5.0
-1,-4,1:5.0
1,-4,1:5.0
2,-4,1:5.0
3,-3,1:5.0
3,-2,1:5.0
3,2,1:5.0
3,3,1:5.0
-3,2,1:5.0
-3,3,1:5.0
-3,-3,1:5.0
-3,-2,1:5.0
1,4,1:5.0
2,4,1:5.0
-1,4,1:5.0
-2,4,1:5.0
3,-1,1:102
3,0,1:102
3,1,1:102
0,-4,1:102
-3,-1,1:102
-3,0,1:102
-3,1,1:102
0,4,1:64.8
1,5,1:50.3
1,-3,1:50.3
2,-2,1:50.2
-2,2,1:50.1
3,-3,2:5.0
3,-2,2:5.0
3,-1,2:5.0
3,0,2:5.0
3,1,2:5.0
3,2,2:5.0
3,3,2:5.0
2,4,2:5.0
1,4,2:5.0
0,4,2:5.0
-1,4,2:5.0
-2,4,2:5.0
-3,3,2:5.0
-3,2,2:5.0
-3,1,2:5.0
-3,0,2:5.0
-3,-1,2:5.0
-3,-2,2:5.0
-3,-3,2:5.0
-2,-4,2:5.0
-1,-4,2:5.0
0,-4,2:5.0
1,-4,2:5.0
2,-4,2:5.0
2,-3,3:5.0
1,-3,3:5.0
0,-3,3:5.0
-1,-3,3:5.0
-2,-3,3:5.0
-2,3,3:5.0
-1,3,3:5.0
0,3,3:5.0
1,3,3:5.0
2,3,3:5.0
2,2,3:5.0
2,1,3:5.0
2,0,3:5.0
2,-1,3:5.0
2,-2,3:5.0
-2,-2,3:5.0
-2,-1,3:5.0
-2,0,3:5.0
-2,1,3:5.0
-2,2,3:5.0
-1,-2,4:5.0
-1,-1,4:5.0
-1,0,4:5.0
-1,1,4:5.0
-1,2,4:5.0
0,2,4:5.0
1,2,4:5.0
1,1,4:5.0
1,0,4:5.0
1,-1,4:5.0
1,-2,4:5.0
0,-2,4:5.0
0,-1,5:5.0
0,1,5:5.0
0,0,6:5.0
