[META]
version=2.0
spawnOnBlockType=2
spawnSunlight=True
spawnDarkness=False
spawnWater=False
spawnLava=False
underFill=True
randomRotation=True
dig=False
tree=True
branch=False
rarity=1
collisionPercentage=0
spawnElevationMin=0
spawnElevationMax=100
spawnInBiome=Forest,Plains,Shrubland,Swampland
[DATA]
-1,0,0:17.0
0,0,0:17.0
0,1,0:17.0
-1,1,0:17.0
-2,-1,0:17.0
-2,0,0:17.0
-2,1,0:17.0
-2,2,0:17.0
-1,2,0:17.0
0,2,0:17.0
1,2,0:17.0
1,1,0:17.0
1,0,0:17.0
1,-1,0:17.0
0,-1,0:17.0
-1,-1,0:17.0
-3,1,0:17.0
-1,3,0:17.0
0,3,0:17.0
0,-2,0:17.0
2,0,0:17.0
-1,0,1:17.0
0,0,1:17.0
0,1,1:17.0
-1,1,1:17.0
-1,3,1:17.0
-1,2,1:17.0
1,1,1:17.0
1,0,1:17.0
0,2,1:17.0
1,-1,1:17.0
2,0,1:17.0
0,-1,1:17.0
0,-2,1:17.0
-1,-1,1:17.0
-2,-1,1:17.0
-2,0,1:17.0
-2,1,1:17.0
-3,1,1:17.0
-2,2,1:17.0
-1,0,2:17.0
0,0,2:17.0
0,1,2:17.0
-1,1,2:17.0
-2,0,2:17.0
-2,1,2:17.0
-1,-1,2:17.0
0,-1,2:17.0
1,0,2:17.0
1,1,2:17.0
-1,2,2:17.0
0,2,2:17.0
-1,0,3:17.0
0,0,3:17.0
0,1,3:17.0
-1,1,3:17.0
-2,1,3:17.0
-1,2,3:17.0
1,1,3:17.0
1,0,3:17.0
0,-1,3:17.0
-1,0,4:17.0
0,0,4:17.0
0,1,4:17.0
-1,1,4:17.0
-2,1,4:17.0
1,0,4:17.0
-1,0,5:17.0
0,0,5:17.0
0,1,5:17.0
-1,1,5:17.0
-2,1,5:17.0
1,0,5:17.0
-1,0,6:17.0
0,0,6:17.0
0,1,6:17.0
-1,1,6:17.0
-2,1,6:17.0
2,5,6:17.0
-6,6,6:17.0
-1,0,7:17.0
0,0,7:17.0
0,1,7:17.0
-1,1,7:17.0
-6,-5,7:17.0
1,5,7:17.0
-5,7,7:17.0
-8,2,7:17.0
-8,1,7:17.0
-9,1,7:17.0
-6,6,7:17.0
4,0,7:17.0
-1,-7,7:17.0
-1,0,8:17.0
0,0,8:17.0
0,1,8:17.0
-1,1,8:17.0
4,-3,8:17.0
-6,-4,8:17.0
1,4,8:17.0
-4,7,8:17.0
-5,7,8:17.0
-8,3,8:17.0
-8,2,8:17.0
-1,-1,8:17.0
4,0,8:17.0
-1,-6,8:17.0
-1,0,9:17.0
0,0,9:17.0
0,1,9:17.0
-1,1,9:17.0
-4,7,9:17.0
2,5,9:17.0
3,-3,9:17.0
-6,-3,9:17.0
0,4,9:17.0
-1,-2,9:17.0
-1,-3,9:17.0
-7,3,9:17.0
-8,3,9:17.0
3,0,9:17.0
1,0,9:17.0
-1,-5,9:17.0
-1,0,10:17.0
0,0,10:17.0
0,1,10:17.0
-1,1,10:17.0
-7,3,10:17.0
-5,-3,10:17.0
2,-3,10:17.0
-4,-3,10:17.0
-4,6,10:17.0
-4,5,10:17.0
-1,4,10:17.0
-1,3,10:17.0
-1,-3,10:17.0
-2,1,10:17.0
2,0,10:17.0
1,6,10:17.0
-1,-4,10:17.0
0,0,11:17.0
0,1,11:17.0
-1,1,11:17.0
-1,0,11:17.0
3,-5,11:17.0
-1,2,11:17.0
-3,-2,11:17.0
-4,-2,11:17.0
-3,-1,11:17.0
-7,2,11:17.0
-6,2,11:17.0
-4,4,11:17.0
-4,3,11:17.0
2,-2,11:17.0
2,-1,11:17.0
-3,-7,11:17.0
-3,-5,11:17.0
-2,-5,11:17.0
-2,-4,11:17.0
-3,2,11:17.0
-3,1,11:17.0
-1,5,11:17.0
1,2,11:17.0
1,1,11:17.0
0,5,11:17.0
1,5,11:17.0
1,7,11:17.0
0,7,11:17.0
-3,-6,12:17.0
1,-1,12:17.0
1,0,12:17.0
-2,-1,12:17.0
-2,0,12:17.0
-5,2,12:17.0
-4,2,12:17.0
-1,0,12:17.0
-1,1,12:17.0
0,1,12:17.0
0,0,12:17.0
-3,5,12:17.0
3,2,12:17.0
2,2,12:17.0
-2,5,12:17.0
2,-5,12:17.0
1,-5,12:17.0
4,3,12:17.0
-5,-1,12:17.0
0,8,12:17.0
-3,6,13:17.0
4,2,13:17.0
-1,0,13:17.0
-1,1,13:17.0
0,1,13:17.0
0,0,13:17.0
0,-4,13:17.0
1,-4,13:17.0
0,-3,13:17.0
3,2,13:17.0
-4,0,13:17.0
-4,-1,13:17.0
0,-3,14:17.0
0,-2,14:17.0
0,-1,14:17.0
-2,1,14:17.0
-3,1,14:17.0
-4,1,14:17.0
-1,0,-1:17.0
0,0,-1:17.0
0,1,-1:17.0
-1,1,-1:17.0
-2,2,-1:17.0
-2,1,-1:17.0
-2,0,-1:17.0
-2,-1,-1:17.0
-1,-1,-1:17.0
0,-1,-1:17.0
1,-1,-1:17.0
1,0,-1:17.0
1,1,-1:17.0
-1,2,-1:17.0
-1,3,-1:17.0
0,2,-1:17.0
-3,1,-1:17.0
0,-2,-1:17.0
2,0,-1:17.0
0,3,-1:17.0
1,2,-1:17.0
-3,0,-1:2
-3,-1,-1:2
-2,-2,-1:2
-1,-2,-1:2
0,-3,-1:2
1,-2,-1:2
2,-1,-1:2
3,0,-1:2
2,1,-1:2
2,2,-1:2
1,3,-1:2
0,4,-1:2
-1,4,-1:2
-2,3,-1:2
-3,2,-1:2
-4,1,-1:2
-3,1,-2:17.0
-2,1,-2:17.0
-2,0,-2:17.0
-2,2,-2:17.0
0,-2,-2:17.0
0,-1,-2:17.0
1,-1,-2:17.0
1,2,-2:17.0
1,1,-2:17.0
0,2,-2:17.0
0,3,-2:17.0
0,-3,-2:3
-1,-2,-2:3
-1,-1,-2:3
1,-2,-2:3
2,-1,-2:3
1,0,-2:3
2,1,-2:3
2,2,-2:3
1,3,-2:3
0,4,-2:3
-1,3,-2:3
-3,2,-2:3
-4,1,-2:3
-3,0,-2:3
-2,-1,-2:3
-2,3,-2:3
-1,2,-2:3
-1,1,-2:3
-1,0,-2:3
0,0,-2:3
0,1,-2:3
0,3,-3:17.0
0,4,-3:17.0
-3,1,-3:17.0
-4,1,-3:17.0
0,-2,-3:17.0
0,-3,-3:17.0
0,-4,-3:3
-1,-3,-3:3
-1,-2,-3:3
1,-3,-3:3
1,-2,-3:3
0,-1,-3:3
-3,0,-3:3
-4,0,-3:3
-5,1,-3:3
-2,1,-3:3
-3,2,-3:3
0,2,-3:3
-1,4,-3:3
-1,3,-3:3
1,3,-3:3
1,4,-3:3
0,5,-3:3
-1,-1,-3:3
-1,0,-3:3
-2,0,-3:3
0,0,-3:3
1,0,-3:3
1,-1,-3:3
1,1,-3:3
1,2,-3:3
0,1,-3:3
-1,1,-3:3
-1,2,-3:3
-2,2,-3:3
-2,-1,-3:3
-4,2,-3:3
