[META]
version=2.0
spawnOnBlockType=2
spawnSunlight=True
spawnDarkness=False
spawnWater=False
spawnLava=False
underFill=True
randomRotation=True
dig=False
tree=True
branch=False
rarity=1
collisionPercentage=5
spawnElevationMin=0
spawnElevationMax=100
spawnInBiome=Forest,Plains,Shrubland,Swampland
[DATA]
-2,-1,0:17.0
-2,0,0:17.0
-2,1,0:17.0
-2,2,0:17.0
1,2,0:17.0
1,1,0:17.0
1,0,0:17.0
1,-1,0:17.0
0,-1,0:17.0
-1,-1,0:17.0
-3,1,0:17.0
-1,3,0:17.0
0,3,0:17.0
0,-2,0:17.0
2,0,0:17.0
1,0,1:17.0
1,-1,1:17.0
2,0,1:17.0
0,-1,1:17.0
0,-2,1:17.0
-1,-1,1:17.0
-2,-1,1:17.0
-2,0,1:17.0
-2,1,1:17.0
-3,1,1:17.0
-2,2,1:17.0
-2,0,2:17.0
-2,1,2:17.0
-1,-1,2:17.0
0,-1,2:17.0
-2,0,3:17.0
-1,-1,3:17.0
-2,2,-1:17.0
-2,1,-1:17.0
-2,0,-1:17.0
-2,-1,-1:17.0
-1,-1,-1:17.0
0,-1,-1:17.0
1,-1,-1:17.0
1,0,-1:17.0
1,1,-1:17.0
-1,3,-1:17.0
-3,1,-1:17.0
0,-2,-1:17.0
2,0,-1:17.0
0,3,-1:17.0
1,2,-1:17.0
-3,0,-1:2
-3,-1,-1:2
-2,-2,-1:2
-1,-2,-1:2
0,-3,-1:2
1,-2,-1:2
2,-1,-1:2
3,0,-1:2
2,1,-1:2
2,2,-1:2
1,3,-1:2
0,4,-1:2
-1,4,-1:2
-2,3,-1:2
-3,2,-1:2
-4,1,-1:2
-1,2,-1:17.0
-1,1,-1:17.0
-1,0,-1:17.0
0,0,-1:17.0
0,1,-1:17.0
0,2,-1:17.0
-3,1,-2:17.0
-2,1,-2:17.0
-2,0,-2:17.0
-2,2,-2:17.0
0,-2,-2:17.0
0,-1,-2:17.0
1,-1,-2:17.0
1,2,-2:17.0
1,1,-2:17.0
0,2,-2:17.0
0,3,-2:17.0
0,-3,-2:3
-1,-2,-2:3
-1,-1,-2:3
1,-2,-2:3
2,-1,-2:3
1,0,-2:3
2,1,-2:3
2,2,-2:3
1,3,-2:3
0,4,-2:3
-1,3,-2:3
-3,2,-2:3
-4,1,-2:3
-3,0,-2:3
-2,-1,-2:3
-2,3,-2:3
-1,2,-2:3
-1,1,-2:3
-1,0,-2:3
0,0,-2:3
0,1,-2:3
0,3,-3:17.0
0,4,-3:17.0
-3,1,-3:17.0
-4,1,-3:17.0
0,-2,-3:17.0
0,-3,-3:17.0
0,-4,-3:3
-1,-3,-3:3
-1,-2,-3:3
1,-3,-3:3
1,-2,-3:3
0,-1,-3:3
-3,0,-3:3
-4,0,-3:3
-5,1,-3:3
-2,1,-3:3
-3,2,-3:3
0,2,-3:3
-1,4,-3:3
-1,3,-3:3
1,3,-3:3
1,4,-3:3
0,5,-3:3
-1,-1,-3:3
-1,0,-3:3
-2,0,-3:3
0,0,-3:3
1,0,-3:3
1,-1,-3:3
1,1,-3:3
1,2,-3:3
0,1,-3:3
-1,1,-3:3
-1,2,-3:3
-2,2,-3:3
-2,-1,-3:3
-4,2,-3:3
