[META]
version=2.0
spawnOnBlockType=2
spawnSunlight=True
spawnDarkness=False
spawnWater=False
spawnLava=False
underFill=True
randomRotation=True
dig=False
tree=False
branch=False
rarity=1
collisionPercentage=5
spawnElevationMin=0
spawnElevationMax=102
groupId=Ruins
groupFrequencyMin=1
groupFrequencyMax=5
groupSeperationMin=0
groupSeperationMax=5
branchLimit=6
spawnInBiome=Forest,Rain Forest,Swampland
[DATA]
-1,-1,0:48
-1,0,0:48
-1,1,0:48
0,1,0:48
1,1,0:48
1,0,0:48
0,-1,0:48
1,-1,0:48
0,-2,0:48
0,2,0:48
0,0,0:89
-1,-1,1:48
-1,0,1:48
-1,1,1:48
0,1,1:48
1,1,1:48
1,0,1:48
1,-1,1:48
0,-1,1:48
0,-2,1:48
0,2,1:48
-1,-1,2:48
-1,0,2:48
-1,1,2:48
0,1,2:48
1,1,2:48
1,0,2:48
1,-1,2:48
0,-1,2:48
0,-2,2:48
0,2,2:48
-1,-1,-1:48
-1,0,-1:48
-1,1,-1:48
0,1,-1:48
0,0,-1:48
0,-1,-1:48
1,-1,-1:48
1,0,-1:48
1,1,-1:48
0,2,-1:48
0,-2,-1:48
-1,-1,3:48
-1,0,3:48
-1,1,3:48
0,1,3:48
0,-1,3:48
1,-1,3:48
1,1,3:48
-1,-1,4:48
-1,0,4:48
-1,1,4:48
0,0,4:48
0,-1,4:48
1,0,4:48
0,1,4:48
-1,-1,5:48
0,-1,5:48
1,-1,5:48
1,0,5:48
0,0,5:48
-1,0,5:48
-1,1,5:48
0,1,5:48
1,1,5:48
0,0,6:48
