[META]
version=2.0
spawnOnBlockType=3,2
spawnSunlight=True
spawnDarkness=False
spawnWater=False
spawnLava=False
underFill=True
randomRotation=True
dig=False
tree=True
branch=False
rarity=10
collisionPercentage=2
spawnElevationMin=0
spawnElevationMax=128
spawnInBiome=All
[DATA]
0,0,0:17.0
0,-1,0:17.0
1,-1,0:17.0
1,0,0:17.0
1,-1,1:17.0
0,-1,1:17.0
0,0,1:17.0
1,0,1:17.0
0,-1,2:17.0
1,-1,2:17.0
1,0,2:17.0
0,0,2:17.0
0,-1,3:17.0
1,-1,3:17.0
1,0,3:17.0
0,0,3:17.0
0,-1,4:17.0
1,-1,4:17.0
1,0,4:17.0
0,0,4:17.0
0,-1,5:17.0
1,-1,5:17.0
1,0,5:17.0
0,0,5:17.0
1,-2,5:17.0
0,-1,6:17.0
1,-1,6:17.0
1,0,6:17.0
0,0,6:17.0
1,-2,6:17.0
1,-3,6:17.0
0,-1,7:17.0
1,-1,7:17.0
1,0,7:17.0
0,0,7:17.0
-1,0,7:17.0
1,-3,7:17.0
1,-4,7:17.0
1,-6,7:18.0
0,-4,7:18.0
0,-5,7:18.0
1,-5,7:18.0
0,-6,7:18.0
1,-7,7:18.0
2,-7,7:18.0
2,-6,7:18.0
2,-5,7:18.0
0,-3,7:18.0
-1,-1,7:18.0
-1,1,7:18.0
-2,1,7:18.0
-2,0,7:18.0
-2,-1,7:18.0
0,-1,8:17.0
1,-1,8:17.0
1,0,8:17.0
0,0,8:17.0
-1,0,8:17.0
-2,0,8:17.0
1,-4,8:17.0
1,-5,8:17.0
1,-6,8:17.0
0,-4,8:18.0
0,-3,8:18.0
2,-5,8:18.0
0,-5,8:18.0
2,-6,8:18.0
-1,-4,8:18.0
2,-3,8:18.0
0,-6,8:18.0
1,-3,8:18.0
0,-2,8:18.0
1,-2,8:18.0
2,-2,8:18.0
-1,-1,8:18.0
-2,-1,8:18.0
-3,0,8:18.0
-2,1,8:18.0
-4,1,8:18.0
-3,1,8:18.0
-1,1,8:18.0
1,-7,8:18.0
0,-1,9:17.0
1,-1,9:17.0
1,0,9:17.0
0,0,9:17.0
1,-5,9:17.0
-2,0,9:17.0
-3,0,9:17.0
-5,0,9:18.0
1,1,9:17.0
-2,-1,9:18.0
-4,-1,9:18.0
-5,-1,9:18.0
-4,-2,9:18.0
-3,-2,9:18.0
-3,-1,9:18.0
-6,-1,9:18.0
-6,0,9:18.0
-5,1,9:18.0
-6,1,9:18.0
-4,1,9:18.0
-4,0,9:18.0
-7,0,9:18.0
-4,2,9:18.0
-1,0,9:18.0
-1,1,9:18.0
-1,-1,9:18.0
0,2,9:18.0
1,2,9:18.0
0,1,9:18.0
2,2,9:18.0
2,1,9:18.0
1,-2,9:18.0
1,-3,9:18.0
0,-4,9:18.0
0,-5,9:18.0
1,-6,9:18.0
2,-6,9:18.0
0,-6,9:18.0
2,-5,9:18.0
2,-4,9:18.0
1,-4,9:18.0
1,-7,9:18.0
0,-3,9:18.0
2,-2,9:18.0
-1,-3,9:18.0
0,-1,10:17.0
1,-1,10:17.0
1,0,10:17.0
0,0,10:17.0
-3,0,10:17.0
-4,0,10:17.0
-5,0,10:17.0
1,1,10:17.0
1,2,10:17.0
0,1,10:18.0
0,2,10:18.0
-1,2,10:18.0
0,3,10:18.0
1,3,10:18.0
1,4,10:18.0
2,3,10:18.0
2,2,10:18.0
2,4,10:18.0
3,3,10:18.0
3,2,10:18.0
0,4,10:18.0
1,5,10:18.0
-2,-1,10:18.0
-3,-1,10:18.0
-3,-2,10:18.0
-4,-2,10:18.0
-4,-3,10:18.0
-4,-1,10:18.0
-5,-1,10:18.0
-5,-2,10:18.0
-6,-1,10:18.0
-7,0,10:18.0
-6,0,10:18.0
-5,1,10:18.0
-6,1,10:18.0
-3,1,10:18.0
-2,0,10:18.0
-1,0,10:18.0
-1,1,10:18.0
-1,-1,10:18.0
1,-2,10:18.0
1,-5,10:18.0
1,-3,10:18.0
0,-1,11:17.0
1,-1,11:17.0
1,0,11:17.0
0,0,11:17.0
-4,0,11:17.0
1,2,11:17.0
1,3,11:17.0
1,5,11:18.0
2,-1,11:17.0
2,-2,11:18.0
3,-2,11:18.0
4,-2,11:18.0
3,-1,11:18.0
2,0,11:18.0
4,-1,11:18.0
0,3,11:18.0
2,2,11:18.0
3,3,11:18.0
2,3,11:18.0
2,4,11:18.0
1,4,11:18.0
0,4,11:18.0
0,5,11:18.0
-1,5,11:18.0
0,6,11:18.0
1,6,11:18.0
0,2,11:18.0
0,1,11:18.0
1,1,11:18.0
-3,0,11:18.0
-3,-1,11:18.0
-4,-1,11:18.0
-5,0,11:18.0
-6,0,11:18.0
-4,1,11:18.0
-5,1,11:18.0
-3,1,11:18.0
-2,0,11:18.0
-2,1,11:18.0
-1,0,11:18.0
-4,2,11:18.0
-3,-2,11:18.0
-4,-2,11:18.0
-5,-1,11:18.0
1,-2,11:18.0
1,3,12:17.0
1,4,12:17.0
1,5,12:17.0
0,0,12:17.0
0,-1,12:17.0
1,-1,12:17.0
1,0,12:17.0
2,-1,12:17.0
3,-1,12:17.0
0,-2,12:17.0
-1,-2,12:18.0
-1,-3,12:18.0
0,-3,12:18.0
0,-4,12:18.0
1,-3,12:18.0
1,-2,12:18.0
2,-2,12:18.0
3,-2,12:18.0
3,-3,12:18.0
4,-2,12:18.0
4,-1,12:18.0
3,0,12:18.0
2,0,12:18.0
0,3,12:18.0
-1,4,12:18.0
0,4,12:18.0
1,6,12:18.0
2,5,12:18.0
3,4,12:18.0
2,4,12:18.0
2,3,12:18.0
-1,3,12:18.0
-2,4,12:18.0
2,6,12:18.0
1,7,12:18.0
2,2,12:18.0
1,2,12:18.0
0,2,12:18.0
0,1,12:18.0
1,1,12:18.0
3,1,12:18.0
2,1,12:18.0
-4,0,12:18.0
-2,0,12:18.0
-1,0,12:18.0
1,4,13:17.0
0,0,13:17.0
0,-1,13:17.0
1,-1,13:17.0
1,0,13:17.0
0,-2,13:17.0
0,-3,13:17.0
3,-1,13:17.0
4,-1,13:17.0
-1,0,13:17.0
-1,-3,13:18.0
-1,-2,13:18.0
-2,-3,13:18.0
-1,-4,13:18.0
0,-4,13:18.0
0,-5,13:18.0
3,-2,13:18.0
4,-2,13:18.0
5,-1,13:18.0
6,-1,13:18.0
4,0,13:18.0
3,0,13:18.0
2,-1,13:18.0
2,0,13:18.0
2,-2,13:18.0
-1,-1,13:18.0
-2,-1,13:18.0
-2,0,13:18.0
-3,0,13:18.0
-2,1,13:18.0
1,3,13:18.0
0,4,13:18.0
0,3,13:18.0
1,2,13:18.0
2,3,13:18.0
1,5,13:18.0
0,5,13:18.0
1,6,13:18.0
2,4,13:18.0
1,1,13:18.0
4,-1,14:17.0
0,-3,14:17.0
0,-4,14:17.0
-2,0,14:17.0
-1,0,14:17.0
0,-1,14:17.0
-1,-1,14:18.0
0,0,14:17.0
1,0,14:17.0
1,-1,14:17.0
2,-1,14:18.0
1,-2,14:18.0
0,-2,14:18.0
-1,-3,14:18.0
1,-3,14:18.0
-1,-4,14:18.0
0,-5,14:18.0
1,-4,14:18.0
3,-1,14:18.0
3,-2,14:18.0
4,-2,14:18.0
5,-1,14:18.0
-2,-1,14:18.0
-3,0,14:18.0
-4,0,14:18.0
-2,1,14:18.0
-1,1,14:18.0
1,4,14:18.0
1,3,14:18.0
1,2,14:18.0
-1,0,15:18.0
-2,0,15:18.0
-3,0,15:18.0
0,0,15:17.0
0,-1,15:17.0
0,-3,15:18.0
3,-1,15:18.0
2,-1,15:18.0
1,-1,15:17.0
1,0,15:17.0
4,-1,15:18.0
0,-4,15:18.0
1,1,15:17.0
1,2,15:17.0
0,-1,16:17.0
0,0,16:17.0
1,0,16:17.0
1,-1,16:17.0
1,5,16:18.0
1,3,16:17.0
1,2,16:17.0
0,3,16:18.0
2,3,16:18.0
2,2,16:18.0
0,2,16:18.0
-1,2,16:18.0
0,1,16:18.0
-2,0,16:18.0
1,3,17:17.0
1,4,17:17.0
1,5,17:17.0
0,0,17:17.0
0,-1,17:17.0
1,-1,17:17.0
1,0,17:17.0
2,-1,17:17.0
3,-1,17:17.0
0,-2,17:17.0
-1,-2,17:18.0
-1,-3,17:18.0
0,-3,17:18.0
0,-4,17:18.0
1,-3,17:18.0
1,-2,17:18.0
2,-2,17:18.0
3,-2,17:18.0
3,-3,17:18.0
4,-2,17:18.0
4,-1,17:18.0
3,0,17:18.0
2,0,17:18.0
0,3,17:18.0
-1,4,17:18.0
0,4,17:18.0
1,6,17:18.0
3,4,17:18.0
2,4,17:18.0
2,3,17:18.0
-1,3,17:18.0
-2,4,17:18.0
2,6,17:18.0
1,7,17:18.0
2,2,17:18.0
1,2,17:18.0
0,2,17:18.0
0,1,17:18.0
1,1,17:18.0
3,1,17:18.0
2,1,17:18.0
0,5,17:18.0
1,4,18:17.0
0,0,18:17.0
0,-1,18:17.0
1,-1,18:17.0
1,0,18:17.0
0,-2,18:17.0
0,-3,18:17.0
3,-1,18:17.0
4,-1,18:17.0
-1,0,18:17.0
-1,-3,18:18.0
-1,-2,18:18.0
-2,-3,18:18.0
-1,-4,18:18.0
0,-4,18:18.0
0,-5,18:18.0
3,-2,18:18.0
4,-2,18:18.0
5,-1,18:18.0
6,-1,18:18.0
4,0,18:18.0
3,0,18:18.0
2,-1,18:18.0
2,0,18:18.0
2,-2,18:18.0
-1,-1,18:18.0
-2,-1,18:18.0
-2,0,18:18.0
-3,0,18:18.0
-2,1,18:18.0
1,3,18:18.0
0,4,18:18.0
0,3,18:18.0
1,2,18:18.0
2,3,18:18.0
1,5,18:18.0
0,5,18:18.0
1,6,18:18.0
2,4,18:18.0
1,1,18:18.0
0,1,18:18.0
4,-1,19:17.0
0,-3,19:17.0
0,-4,19:17.0
-2,0,19:17.0
-1,0,19:17.0
0,-1,19:18.0
-1,-1,19:18.0
0,0,19:18.0
1,0,19:18.0
1,-1,19:18.0
2,-1,19:18.0
1,-2,19:18.0
0,-2,19:18.0
-1,-3,19:18.0
1,-3,19:18.0
-1,-4,19:18.0
0,-5,19:18.0
1,-4,19:18.0
3,-1,19:18.0
3,-2,19:18.0
4,-2,19:18.0
5,-1,19:18.0
-2,-1,19:18.0
-3,0,19:18.0
-4,0,19:18.0
-2,1,19:18.0
-1,1,19:18.0
1,4,19:18.0
1,5,19:18.0
1,6,19:18.0
1,1,19:18.0
1,2,19:18.0
0,4,19:18.0
0,1,19:18.0
-1,0,20:18.0
-2,0,20:18.0
-3,0,20:18.0
0,0,20:18.0
0,-1,20:18.0
0,-3,20:18.0
3,-1,20:18.0
2,-1,20:18.0
1,-1,20:18.0
1,0,20:18.0
4,-1,20:18.0
0,-4,20:18.0
1,4,20:18.0
1,5,20:18.0
1,1,20:18.0
0,1,20:18.0
1,2,20:18.0
0,4,20:18.0
0,-1,21:18.0
0,0,21:18.0
1,-1,21:18.0
1,0,21:18.0
-1,0,21:18.0
1,1,21:18.0
1,2,21:18.0
0,0,22:18.0
1,0,22:18.0
1,1,22:18.0
