[META]
version=2.0
spawnOnBlockType=12
spawnSunlight=True
spawnDarkness=False
spawnWater=False
spawnLava=False
underFill=True
randomRotation=True
dig=False
tree=True
branch=False
rarity=1
collisionPercentage=2
spawnElevationMin=0
spawnElevationMax=128
spawnInBiome=Desert
[DATA]
0,0,0:85
0,0,1:85
0,0,2:85
0,0,3:85
0,0,4:85
0,0,5:85
0,0,6:17.0
-3,0,6:18.0
0,-3,6:18.0
0,3,6:18.0
3,0,6:18.0
0,0,7:18.0
-1,0,7:18.0
1,0,7:18.0
0,-1,7:18.0
0,1,7:18.0
0,-2,7:18.0
0,2,7:18.0
-2,0,7:18.0
2,0,7:18.0
-1,-1,7:18.0
1,1,7:18.0
-1,1,7:18.0
1,-1,7:18.0
0,-3,7:18.0
0,3,7:18.0
-3,0,7:18.0
3,0,7:18.0
-2,0,8:18.0
-1,0,8:18.0
0,-2,8:18.0
0,-1,8:18.0
0,1,8:18.0
0,2,8:18.0
1,0,8:18.0
2,0,8:18.0
