[META]
version=2.0
spawnOnBlockType=2
spawnSunlight=True
spawnDarkness=False
spawnWater=False
spawnLava=False
underFill=True
randomRotation=True
dig=False
tree=True
branch=False
rarity=10
collisionPercentage=2
spawnElevationMin=0
spawnElevationMax=100
spawnInBiome=All
[DATA]
0,0,0:17.1
0,0,1:17.1
0,0,2:17.1
0,0,3:17.1
0,0,4:17.1
0,0,5:17.1
0,0,6:17.1
0,0,8:17.1
1,-1,8:18.0
0,0,9:17.1
-1,1,9:17.1
-1,0,9:18.0
-2,1,9:18.0
-1,2,9:18.0
0,1,9:18.0
0,0,10:17.1
-1,1,10:18.0
0,0,11:17.1
-1,-1,11:17.1
0,0,12:17.1
-2,-1,12:18.0
-1,0,12:18.0
-1,-2,12:18.0
-1,-1,12:18.0
0,-1,12:18.0
0,0,13:17.1
1,1,13:17.1
0,1,13:18.0
1,0,13:18.0
2,1,13:18.0
1,2,13:18.0
0,0,14:17.1
1,1,14:18.0
0,0,7:17.1
1,-1,7:17.1
1,-2,7:18.0
0,-1,7:18.0
2,-1,7:18.0
1,0,7:18.0
0,0,15:17.1
-1,-1,15:17.1
1,-1,15:17.1
-2,-1,15:18.0
-1,-2,15:18.0
0,-1,15:18.0
1,-2,15:18.0
2,-1,15:18.0
1,0,15:18.0
0,1,15:18.0
-1,0,15:18.0
-1,-1,16:18.0
0,0,16:17.1
1,-1,16:18.0
-1,1,16:17.1
-2,1,16:18.0
-1,0,16:18.0
-1,2,16:18.0
0,1,16:18.0
-1,1,17:18.0
0,0,17:17.1
0,0,18:17.1
-1,0,18:18.0
0,-1,18:18.0
0,1,18:18.0
1,0,18:18.0
0,0,19:18.0
