[META]
version=2.0
spawnOnBlockType=2
spawnSunlight=True
spawnDarkness=True
spawnWater=False
spawnLava=False
underFill=True
randomRotation=True
dig=True
tree=False
branch=False
rarity=1
collisionPercentage=5
spawnElevationMin=0
spawnElevationMax=100
spawnInBiome=All
[DATA]
-1,-1,0:48
-1,0,0:48
-1,1,0:48
0,1,0:48
1,1,0:48
1,0,0:48
1,-1,0:48
0,-1,0:48
-2,-1,0:48
-2,0,0:48
-2,1,0:48
-1,2,0:48
0,2,0:48
1,2,0:48
2,1,0:48
2,0,0:48
2,-1,0:48
1,-2,0:48
0,-2,0:48
-1,-2,0:48
0,0,0:48
2,-2,0:48
-2,-2,0:48
-2,2,0:48
2,2,0:48
-2,-2,1:48
-2,-1,1:48
-2,0,1:48
-2,1,1:48
-2,2,1:48
-1,2,1:48
0,2,1:48
1,2,1:48
2,2,1:48
-1,-2,1:48
0,-2,1:48
1,-2,1:48
2,-2,1:48
1,-1,1:48
1,0,1:48
1,1,1:48
0,1,1:48
-1,1,1:48
-1,0,1:48
-1,-1,1:48
0,-1,1:48
0,0,1:89
2,-2,2:48
2,-1,2:48
2,0,2:48
2,1,2:48
2,2,2:48
1,-2,2:48
0,-2,2:48
-1,-2,2:48
-2,-2,2:48
-2,-1,2:48
-2,0,2:48
-2,1,2:48
-2,2,2:48
-1,2,2:48
0,2,2:48
1,2,2:48
-1,-1,2:48
-1,0,2:48
-1,1,2:48
0,1,2:48
1,1,2:48
1,0,2:48
1,-1,2:48
0,-1,2:48
2,0,3:48
2,-2,3:48
2,2,3:48
0,2,3:48
1,2,3:48
-1,2,3:48
-2,2,3:48
-2,1,3:48
-2,0,3:48
-2,-1,3:48
-2,-2,3:48
-1,-2,3:48
0,-2,3:48
1,-2,3:48
-1,-1,3:48
-1,0,3:48
-1,1,3:48
1,0,3:48
2,-1,4:48
2,0,4:48
2,1,4:48
1,2,4:48
0,2,4:48
-1,2,4:48
-2,1,4:48
-2,0,4:48
-2,-1,4:48
-1,-2,4:48
0,-2,4:48
1,-2,4:48
-1,-1,4:48
-1,0,4:48
-1,1,4:48
0,1,4:48
1,1,4:48
1,0,4:48
1,-1,4:48
0,-1,4:48
0,0,4:48
-2,-2,4:48
2,-2,4:48
2,2,4:48
-2,2,4:48
-1,-1,-1:48
-1,0,-1:48
-1,1,-1:48
0,1,-1:48
1,1,-1:48
1,0,-1:48
1,-1,-1:48
0,-1,-1:48
0,0,-1:48
